<mujoco model="skyvortex">
  <compiler autolimits="true" angle="radian" assetdir="assets"/>

  <option timestep="0.01" gravity="0 0 -9.81" density="1.225" viscosity=""/>
  
  <default>
    <default class="skyvortex">
      <default class="visual">
        <geom group="2" contype="0" conaffinity="0"/>
      </default>
      <default class="collision">
        <geom group="3"/>
      </default>
    </default>
  </default>
    
  <asset>
    <mesh name="base_link" file="base_link.STL"/> <!-- Ensure file path is correct and accessible -->
    <mesh name="operator_Link" file="operator_Link.STL"/>
    <mesh name="end_Link" file="end_Link.STL"/>
    <mesh name="camera_Link" file="camera_Link.STL"/>
    <mesh name="rotor1_Link" file="rotor1_Link.STL"/>
    <mesh name="rotor2_Link" file="rotor2_Link.STL"/>
    <mesh name="rotor3_Link" file="rotor3_Link.STL"/>
    <mesh name="rotor4_Link" file="rotor4_Link.STL"/>
    <mesh name="rotor5_Link" file="rotor5_Link.STL"/>
    <mesh name="rotor6_Link" file="rotor6_Link.STL"/>
    <mesh name="end_effector_base_link" file="end_effector_base_link.STL"/>
    <mesh name="connect_Link" file="connect_Link.STL"/>
    <mesh name="move_base_Link" file="move_base_Link.STL"/>
    <mesh name="wheel2_Link" file="wheel2_Link.STL"/>
    <mesh name="wheel1_Link" file="wheel1_Link.STL"/>
    <mesh name="wheel3_Link" file="wheel3_Link.STL"/>
    <mesh name="move_base_chassis_coll" file="move_base_chassis_coll.STL"/>
    <mesh name="move_base_camera_coll000" file="move_base_camera_coll000.STL"/>
    <mesh name="move_base_camera_coll001" file="move_base_camera_coll001.STL"/>
    <mesh name="operator_coll" file="operator_coll.STL"/>
  </asset>

  <worldbody>
    <body name="base_link" pos="0 0 0.5" childclass="skyvortex">
      <inertial pos="0 -0.002137 0.004638" mass="4.10772" fullinertia="0.1560383 0.1567601 0.290817 0.0 0.0 0.0"/>
      <joint name="free_joint" type="free"/>
      <geom class="visual" type="mesh" rgba="0.792157 0.819608 0.933333 1" mesh="base_link"/>
      <geom name="leg1" class="collision" type="cylinder" size="0.030 0.175" pos="0.030677 -0.25355 -0.17398" quat="0.95305 -0.122402 -0.152147 -0.231442"/>
      <geom name="leg2" class="collision" type="cylinder" size="0.030 0.175" pos="-0.23492 -0.10021 -0.17398" quat="0.718355 0.152077 0.119159 0.668311"/>
      <geom name="leg3" class="collision" type="cylinder" size="0.030 0.175" pos="0.23492 0.10021 -0.17398" quat="0.718355 -0.152077 -0.119159 0.668311"/>
      <geom name="leg4" class="collision" type="cylinder" size="0.030 0.175" pos="-0.030677 0.25355 -0.17398" quat="0.95305 0.122402 0.152147 -0.231442"/>
      <geom name="rotor1" class="collision" type="cylinder" size="0.228 0.02" pos="0.44207 0.2778 0.033856" quat="0.922577 -0.190485 -0.184513 -0.280218"/>
      <geom name="rotor2" class="collision" type="cylinder" size="0.228 0.02" pos="0.019547 0.52175 0.033856" quat="0.683013 0.183012 0.183012 0.683013"/>
      <geom name="rotor3" class="collision" type="cylinder" size="0.228 0.02" pos="-0.46162 0.24395 0.033856" quat="0.922493 0.190542 -0.184455 0.280495"/>
      <geom name="rotor4" class="collision" type="cylinder" size="0.228 0.02" pos="-0.46162 -0.24395 0.033856" quat="0.922577 -0.190485 -0.184513 -0.280218"/>
      <geom name="rotor5" class="collision" type="cylinder" size="0.228 0.02" pos="0.019547 -0.52175 0.033856" quat="0.683013 0.183012 0.183012 0.683013"/>
      <geom name="rotor6" class="collision" type="cylinder" size="0.228 0.02" pos="0.442074 -0.277802 0.0338557" quat="0.922493 0.190542 -0.184455 0.280495"/>
      <body name="operator_Link" pos="0.000870575 0.000171621 0.0284551">
        <inertial pos="-0.0800128 0.00299566 0.0832562" quat="0.708676 -0.0840426 -0.0852993 0.695297" mass="2.81664" diaginertia="0.0603819 0.0522805 0.00984655"/>
        <joint name="operator_1_joint" pos="0 0 0" axis="-0.0169901 -0.999856 0" actuatorfrcrange="-100 100" range="-3.14159 3.14159"/>
        <geom class="visual" type="mesh" rgba="0.792157 0.819608 0.933333 1" mesh="operator_Link" />
        <geom class="visual" group="4" pos="0.832191 -0.014141 0.480535" quat="0.865994 0.00424768 0.499982 -0.0073572" type="mesh" rgba="1 1 1 1" mesh="end_Link" />
        <geom class="visual" group="4" pos="-0.1084 0.001842 0.21154" quat="0.965891 -0.00219878 -0.25881 -0.00820592" type="mesh" rgba="0 1 0 1" mesh="camera_Link" />
        <geom class="visual" pos="0.257683 -0.00437869 0.148795" quat="0.350537 0.607148 -0.617553 -0.356544" type="mesh" rgba="0.89804 0.91765 0.92941 1" mesh="end_effector_base_link" />
        <geom name="operator_link_coll" class="collision" type="cylinder" size="0.04 0.4" pos="0.4 0 0.235" quat="0.86271 0.0129416 0.505476 -0.00758272"/>
        <geom name="operator_coll" class="collision" type="mesh" mesh="operator_coll" />
        <body name="connect_Link" pos="0.515159 -0.00875385 0.29747" quat="0.350537 0.607148 -0.617553 -0.356544">
          <inertial pos="0.0002302 -0.00830799 -0.339949" quat="0.999798 -0.0199876 0.00190355 -0.000853698" mass="0.424535" diaginertia="0.00261436 0.00256116 0.000223766"/>
          <joint name="connect_joint" pos="0 0 0" stiffness="1000" damping="100" axis="0 0 1" type="slide" range="-0.1 0.1"/>
          <geom class="visual" type="mesh" rgba="0.49804 0.49804 0.49804 1" mesh="connect_Link" />
          <geom class="visual" pos="0 0 -0.4115" quat="1 0 0 0" type="mesh" rgba="1 1 1 1" mesh="move_base_Link" />
          <geom class="collision" pos="0 0 -0.4115" quat="1 0 0 0" type="mesh" rgba="0.7 0.2 0.2 1" mesh="move_base_chassis_coll" />
          <geom class="collision" pos="0 0 -0.4115" quat="1 0 0 0" type="mesh" rgba="0.7 0.2 0.2 1" mesh="move_base_camera_coll000" />
          <geom class="collision" pos="0 0 -0.4115" quat="1 0 0 0" type="mesh" rgba="0.7 0.2 0.2 1" mesh="move_base_camera_coll001" />
          <body name="wheel2_Link" pos="0.07403 -0.042741 -0.4" quat="0.499998 0 0 -0.866027">
            <inertial pos="-1.484e-06 -0.002344 1.5339e-06" quat="0.653327 0.27058 0.270616 0.653236" mass="0.040979" diaginertia="4.0926e-06 2.48188e-06 2.48152e-06"/>
            <joint name="wheel2_joint" pos="0 0 0" axis="0 1 0" damping="0.01"/>
            <geom class="visual" type="mesh" rgba="0.77647 0.75686 0.73725 1" mesh="wheel2_Link" />
            <geom class="collision" type="mesh" rgba="0.7 0.2 0.2 1" mesh="wheel2_Link" />
          </body>
          <body name="wheel1_Link" pos="0 0.085482 -0.4">
            <inertial pos="-1.4728e-06 -0.0024779 -4.285e-05" quat="0.653327 0.27058 0.270616 0.653236" mass="0.041284" diaginertia="4.093e-06 2.48378e-06 2.48342e-06"/>
            <joint name="wheel1_joint" pos="0 0 0" axis="0 1 0" damping="0.01"/>
            <geom class="visual" type="mesh" rgba="0.77647 0.75686 0.73725 1" mesh="wheel1_Link" />
            <geom class="collision" type="mesh" rgba="0.7 0.2 0.2 1" mesh="wheel1_Link" />
          </body>
          <body name="wheel3_Link" pos="-0.07403 -0.042741 -0.4" quat="0.499998 0 0 0.866027">
            <inertial pos="-1.4839e-06 -0.002344 1.5339e-06" quat="0.653327 0.27058 0.270616 0.653236" mass="0.040979" diaginertia="4.0926e-06 2.48188e-06 2.48152e-06"/>
            <joint name="wheel3_joint" pos="0 0 0" axis="0 1 0" damping="0.01"/>
            <geom class="visual" type="mesh" rgba="0.77647 0.75686 0.73725 1" mesh="wheel3_Link" />
            <geom class="collision" type="mesh" rgba="0.7 0.2 0.2 1" mesh="wheel3_Link" />
          </body>
        </body>
      </body>
      <body name="rotor1_Link" pos="0.44207 0.2778 0.033856">
        <inertial pos="0.0012692 0.000215034 -0.000505322" quat="0.456657 0.409329 -0.289671 0.73485" mass="0.0159144" diaginertia="0.00021918 0.000218418 7.88807e-07"/>
        <joint name="rotor_0_joint" pos="0 0 0" axis="-0.249999 0.433009 0.866028"/>
        <geom class="visual" type="mesh" rgba="0.792157 0.819608 0.933333 1" mesh="rotor1_Link" />
      </body>
      <body name="rotor2_Link" pos="0.019547 0.52175 0.033856">
        <inertial pos="0.000229104 0.00102773 -0.000896447" quat="0.239184 0.83267 -0.136765 0.480362" mass="0.0159143" diaginertia="0.000219178 0.000218416 7.88783e-07"/>
        <joint name="rotor_1_joint" pos="0 0 0" axis="0.499998 0 0.866027"/>
        <geom class="visual" type="mesh" rgba="0.792157 0.819608 0.933333 1" mesh="rotor2_Link" />
      </body>
      <body name="rotor3_Link" pos="-0.46162 0.24395 0.033856">
        <inertial pos="0.000358062 0.00133569 7.0368e-06" quat="-0.091344 0.605675 -0.24228 0.752406" mass="0.0159143" diaginertia="0.000219178 0.000218416 7.88771e-07"/>
        <joint name="rotor_2_joint" pos="0 0 0" axis="-0.249999 -0.433009 0.866028"/>
        <geom class="visual" type="mesh" rgba="0.792157 0.819608 0.933333 1" mesh="rotor3_Link" />
      </body>
      <body name="rotor4_Link" pos="-0.46162 -0.24395 0.033856">
        <inertial pos="-0.000700003 -0.00112158 -0.000405457" quat="0.366722 0.489556 -0.142372 0.77819" mass="0.0159143" diaginertia="0.000219178 0.000218416 7.88784e-07"/>
        <joint name="rotor_3_joint" pos="0 0 0" axis="-0.249999 0.433009 0.866028"/>
        <geom class="visual" type="mesh" rgba="0.792157 0.819608 0.933333 1" mesh="rotor4_Link" />
      </body>
      <body name="rotor5_Link" pos="0.019547 -0.52175 0.033856">
        <inertial pos="0.000182409 -0.0010598 -0.000869503" quat="-0.220466 0.837797 0.12595 0.483351" mass="0.0159144" diaginertia="0.000219179 0.000218417 7.88808e-07"/>
        <joint name="rotor_4_joint" pos="0 0 0" axis="0.499998 0 0.866027"/>
        <geom class="visual" type="mesh" rgba="0.792157 0.819608 0.933333 1" mesh="rotor5_Link" />
      </body>
      <body name="rotor6_Link" pos="0.442074 -0.277802 0.0338557">
        <inertial pos="-2.69533e-05 -0.000762619 -0.00115327" quat="-0.093145 0.605094 -0.243729 0.752185" mass="0.0159143" diaginertia="0.000219177 0.000218415 7.88769e-07"/>
        <joint name="rotor_5_joint" pos="0 0 0" axis="-0.25 -0.433013 0.866025"/>
        <geom class="visual" type="mesh" rgba="0.792157 0.819608 0.933333 1" mesh="rotor6_Link" />
      </body>
    </body>
  </worldbody>

  <actuator>
    <position name="operator_joint" joint="operator_1_joint" kp="30" kv="10" inheritrange="1.0"/>
  </actuator>
</mujoco>